<?xml version='1.0'?>
<sdf version='1.4'>
    <model name="my_robot">
        <!-- <static>true</static> -->
        <static>false</static>
        <self_collide>1</self_collide>

        <!-- CHASIS -->
        <link name='chassis'>
            <pose>0 0 .05 0 0 0</pose>
  	    <inertial>
        	<mass>50</mass>
            </inertial>
            <collision name='collision'>
                <geometry>
                    <cylinder>
                        <radius>.5</radius>
                        <length>.1</length>
                    </cylinder>
                </geometry>
            </collision>

            <visual name='visual'>
                <geometry>
                    <cylinder>
                        <radius>.5</radius>
                        <length>.1</length>
                    </cylinder>
                </geometry>
            </visual>
        </link>

        <!-- ARM ONE -->
        <link name='arm1'>
            <pose>0 0 .125 0 0 0</pose>
  	    <inertial>
        	<mass>5</mass>
            </inertial>
            <collision name='collision'>
                <geometry>
                    <cylinder>
                        <radius>.1</radius>
                        <length>.05</length>
                    </cylinder>
                </geometry>
            </collision>

            <visual name='visual'>
                <geometry>
                    <cylinder>
                        <radius>.1</radius>
                        <length>.05</length>
                    </cylinder>
                </geometry>
            </visual>
        </link>

        <!-- ARM TWO -->
        <link name='arm2'>
            <pose>0 0 1.15 0 0 0</pose>
  	    <inertial>
        	<mass>0.85<mass>
            </inertial>
            <collision name='collision'>
                <geometry>
                    <cylinder>
                        <radius>.05</radius>
                        <length>2.0</length>
                    </cylinder>
                </geometry>
            </collision>

            <visual name='visual'>
                <geometry>
                    <cylinder>
                        <radius>.05</radius>
                        <length>2.0</length>
                    </cylinder>
                </geometry>
            </visual>
        </link>

        <!-- ARM THREE -->
        <link name='arm3'>
            <pose>0 0 2.65 0 0 0</pose>
  	    <inertial>
        	<mass>0.5</mass>
            </inertial>
            <collision name='collision'>
                <geometry>
                    <cylinder>
                        <radius>.05</radius>
                        <length>1.0</length>
                    </cylinder>
                </geometry>
            </collision>

            <visual name='visual'>
                <geometry>
                    <cylinder>
                        <radius>.05</radius>
                        <length>1.0</length>
                    </cylinder>
                </geometry>
            </visual>
        </link>

        <!-- ARM FOUR -->
        <link name='arm4'>
            <pose>0 0 3.4 0 0 0</pose>
  	    <inertial>
        	<mass>0.05</mass>
            </inertial>
            <collision name='collision'>
                <geometry>
                    <cylinder>
                        <radius>.05</radius>
                        <length>0.5</length>
                    </cylinder>
                </geometry>
            </collision>

            <visual name='visual'>
                <geometry>
                    <cylinder>
                        <radius>.05</radius>
                        <length>0.5</length>
                    </cylinder>
                </geometry>
            </visual>
        </link>

        <!-- JOINT - CHASIS_ARM1_JOINT -->
        <joint type="revolute" name="chasis_arm1_joint">
            <pose>0 0 -0.025 0 0 0</pose>
            <child>arm1</child>
            <parent>chassis</parent>
            <axis>
                <xyz>0 0 1</xyz>
            </axis>
        </joint>

        <!-- JOINT - ARM1_ARM_2_JOINT -->
         <joint type="revolute" name="arm1_arm2_joint">
            <pose>0 0 -1 0 0 0</pose>
            <child>arm2</child>
            <parent>arm1</parent>
            <axis>
                <xyz>1 0 0</xyz>
            </axis>
        </joint>

        <!-- JOINT - ARM2_ARM3_JOINT -->
        <joint type="revolute" name="arm2_arm3_joint">
            <pose>0 0 -0.5 0 0 0</pose>
            <child>arm3</child>
            <parent>arm2</parent>
            <axis>
                <xyz>1 0 0</xyz>
            </axis>
        </joint>
        <!-- JOINT - ARM3_ARM3_JOINT -->
        <joint type="revolute" name="arm3_arm4_joint">
            <pose>0 0 -0.25 0 0 0</pose>
            <child>arm4</child>
            <parent>arm3</parent>
            <axis>
                <xyz>1 0 0</xyz>
            </axis>
        </joint>
        <plugin name="arm_control" filename="libcontroller.so" />
        <!-- <plugin name="arm_control" filename="libshow_joint_angles.so" /> -->


    </model>
</sdf>
